Workbook

Sheet Tracker
A1: # | B1: Pattern | C1: Problem | D1: Difficulty | E1: Date Attempted | F1: Solved First Try? | G1: Time Complexity | H1: Space Complexity | I1: Status | J1: Date Flagged | K1: Review Due (2wk) | L1: Reviewed Cold? | M1: Notes
A2: 1 | B2: Arrays & Hashing | C2: Contains Duplicate | D2: Easy | K2: =IF(J2="","",J2+14)
A3: 2 | B3: Arrays & Hashing | C3: Valid Anagram | D3: Easy | K3: =IF(J3="","",J3+14)
A4: 3 | B4: Arrays & Hashing | C4: Two Sum | D4: Easy | K4: =IF(J4="","",J4+14)
A5: 4 | B5: Arrays & Hashing | C5: Group Anagrams | D5: Medium | K5: =IF(J5="","",J5+14)
A6: 5 | B6: Arrays & Hashing | C6: Top K Frequent Elements | D6: Medium | K6: =IF(J6="","",J6+14)
A7: 6 | B7: Arrays & Hashing | C7: Encode and Decode Strings | D7: Medium | K7: =IF(J7="","",J7+14)
A8: 7 | B8: Arrays & Hashing | C8: Product of Array Except Self | D8: Medium | K8: =IF(J8="","",J8+14)
A9: 8 | B9: Arrays & Hashing | C9: Valid Sudoku | D9: Medium | K9: =IF(J9="","",J9+14)
A10: 9 | B10: Arrays & Hashing | C10: Longest Consecutive Sequence | D10: Medium | K10: =IF(J10="","",J10+14)
A11: 10 | B11: Two Pointers | C11: Valid Palindrome | D11: Easy | K11: =IF(J11="","",J11+14)
A12: 11 | B12: Two Pointers | C12: Two Sum II Input Array Is Sorted | D12: Medium | K12: =IF(J12="","",J12+14)
A13: 12 | B13: Two Pointers | C13: 3Sum | D13: Medium | K13: =IF(J13="","",J13+14)
... A57: 56 | B57: Trees | C57: Validate Binary Search Tree | D57: Medium | K57: =IF(J57="","",J57+14)
A58: 57 | B58: Trees | C58: Kth Smallest Element in a BST | D58: Medium | E58: 46213 | F58: No | I58: Solved | K58: =IF(J58="","",J58+14)
A59: 58 | B59: Trees | C59: Construct Binary Tree from Preorder and Inorder Traversal | D59: Medium | E59: 46214 | F59: No | I59: Solved | K59: =IF(J59="","",J59+14)
A60: 59 | B60: Trees | C60: Binary Tree Maximum Path Sum | D60: Hard | E60: 46217 | F60: No | I60: Solved with Help | J60: 46217 | K60: =IF(J60="","",J60+14) -> 46231
A61: 60 | B61: Trees | C61: Serialize and Deserialize Binary Tree | D61: Hard | E61: 46218 | F61: Yes | I61: Solved | K61: =IF(J61="","",J61+14)
A62: 61 | B62: Tries | C62: Implement Trie (Prefix Tree) | D62: Medium | E62: 46233 | F62: No | I62: Solved with Help | J62: 46221 | K62: 46247
A63: 62 | B63: Tries | C63: Design Add and Search Words Data Structure | D63: Medium
A64: 63 | B64: Tries | C64: Word Search II | D64: Hard
A65: 64 | B65: Heap / Priority Queue | C65: Kth Largest Element in a Stream | D65: Easy | K65: =IF(J65="","",J65+14)
A66: 65 | B66: Heap / Priority Queue | C66: Last Stone Weight | D66: Easy | K66: =IF(J66="","",J66+14)
A67: 66 | B67: Heap / Priority Queue | C67: K Closest Points to Origin | D67: Medium | K67: =IF(J67="","",J67+14)
A68: 67 | B68: Heap / Priority Queue | C68: Kth Largest Element in an Array | D68: Medium | K68: =IF(J68="","",J68+14)
A69: 68 | B69: Heap / Priority Queue | C69: Task Scheduler | D69: Medium | K69: =IF(J69="","",J69+14)
A70: 69 | B70: Heap / Priority Queue | C70: Design Twitter | D70: Medium | K70: =IF(J70="","",J70+14)
A71: 70 | B71: Heap / Priority Queue | C71: Find Median from Data Stream | D71: Hard | E71: 46219 | F71: No | I71: Solved | K71: =IF(J71="","",J71+14)
A72: 71 | B72: Backtracking | C72: Subsets | D72: Medium | K72: =IF(J72="","",J72+14)
A73: 72 | B73: Backtracking | C73: Combination Sum | D73: Medium | E73: 46221 | F73: No | I73: Solved | J73: 46221 | K73: =IF(J73="","",J73+14) -> 46235
A74: 73 | B74: Backtracking | C74: Permutations | D74: Medium | K74: =IF(J74="","",J74+14)
A75: 74 | B75: Backtracking | C75: Subsets II | D75: Medium | K75: =IF(J75="","",J75+14)
A76: 75 | B76: Backtracking | C76: Combination Sum II | D76: Medium | K76: =IF(J76="","",J76+14)
A77: 76 | B77: Backtracking | C77: Word Search | D77: Medium | E77: 46231 | F77: No | I77: Solved with Help | J77: 46231 | K77: =IF(J77="","",J77+14) -> 46245
A78: 77 | B78: Backtracking | C78: Palindrome Partitioning | D78: Medium | K78: =IF(J78="","",J78+14)
A79: 78 | B79: Backtracking | C79: Letter Combinations of a Phone Number | D79: Medium | K79: =IF(J79="","",J79+14)
A80: 79 | B80: Backtracking | C80: N-Queens | D80: Hard | K80: =IF(J80="","",J80+14)
A81: 80 | B81: Graphs | C81: Number of Islands | D81: Medium | K81: =IF(J81="","",J81+14)
A82: 81 | B82: Graphs | C82: Clone Graph | D82: Medium | K82: =IF(J82="","",J82+14)
A83: 82 | B83: Graphs | C83: Max Area of Island | D83: Medium | K83: =IF(J83="","",J83+14)
...

Sheet Dashboard
A1: NeetCode 150 Progress
A3: Total Problems | B3: =COUNTA(Tracker!C2:C151) -> 150
A4: Solved | B4: =COUNTIF(Tracker!I2:I151,"Solved") -> 5
A5: Solved with Help | B5: =COUNTIF(Tracker!I2:I151,"Solved with Help") -> 3
A6: Attempted (not solved) | B6: =COUNTIF(Tracker!I2:I151,"Attempted") -> 0
A7: Not Started | B7: =COUNTA(Tracker!C2:C151)-COUNTIF(Tracker!I2:I151,"Solved")-COUNTIF(Tracker!I2:I151,"Solved with Help")-COUNTIF(Tracker!I2:I151,"Attempted") -> 142
A8: % Complete (fully) | B8: =(COUNTIF(Tracker!I2:I151,"Solved")+COUNTIF(Tracker!I2:I151,"Solved with Help"))/COUNTA(Tracker!C2:C151) -> 0.053333333
A9: Flagged for Sunday Review (overdue) | B9: =COUNTIFS(Tracker!K2:K151,"<="&TODAY(),Tracker!K2:K151,"<>",Tracker!L2:L151,"<>Yes") -> 1
A11: By Difficulty
A12: Easy | B12: =COUNTIFS(Tracker!D2:D151,"Easy",Tracker!I2:I151,"Solved")&"/"&COUNTIF(Tracker!D2:D151,"Easy") -> 0/28
A13: Medium | B13: =COUNTIFS(Tracker!D2:D151,"Medium",Tracker!I2:I151,"Solved")&"/"&COUNTIF(Tracker!D2:D151,"Medium") -> 3/101
A14: Hard | B14: =COUNTIFS(Tracker!D2:D151,"Hard",Tracker!I2:I151,"Solved")&"/"&COUNTIF(Tracker!D2:D151,"Hard") -> 2/21
A16: How to use this tracker
A17: 1. Attempt a problem. Fill Date Attempted.
A18: 2. Solved it? Set Status = Solved, log Time/Space Complexity, move on.
A19: 3. Didn't solve it? Read the solution fully, understand why it works,
A20: close it, re-implement from scratch without copying.
A21: Set Status = Solved with Help, and set Date Flagged = today.
A22: Review Due auto-calculates as +14 days.
A23: 4. Every Sunday: check Dashboard 'Flagged for Sunday Review (overdue)'.
A24: Re-attempt those cold. If solved now, set Reviewed Cold? = Yes.
